Workbook

Sheet Judul
C11: PENGISIAN SCORE RMI
C12: BUMN

Sheet Reviu Dokumen
B2: SUB DIMENSI | D2: PARAMETER | F2: KRITERIA PENILAIAN | H2: DOKUMEN YANG HARUS DISIAPKAN | J2: REVIU DOKUMEN | L2: SCREEN SHOOT DOKUMEN | M2: SCORE KRITERIA | N2: SCORE PARAMETER
B3: 1 | C3: Budaya Risiko | D3: 1 | E3: Internalisasi budaya risiko dalam budaya perusahaan. | F3: a | G3: Telah ada program penanaman budaya risiko yang sedang dijalankan (misal risk awards, sosialisasi, risk townhall, dan sebagainya) dan terdapat program sadar risiko, saat ini dilakukan secara rutin dan lebih sering (lebih dari satu kali dalam setahun). | H3: 1 | I3: Dokumen laporan pelaksanaan program penanaman budaya risiko dan sadar risiko di tahun yang diukur (misal sosialisasi, kampanye, risk award dan sebagainya serta laporan pelaksanaannya).
F4: b | G4: Tanggung jawab pengembangan budaya risiko secara jelas diemban dan tercantum dalam uraian jabatan tidak hanya untuk Lini Kedua, tetapi juga di semua lini (khususnya yang memegang posisi manajerial). | H4: 1 | I4: Cuplikan dokumen jobdesk manajer lini pertama, lini kedua, dan lini ketiga yang mencantumkan adanya tanggung jawab pengembangan budaya risiko.
F5: c | G5: Direksi berperan aktif untuk mengembangkan budaya Manajemen Risiko. | H5: 1 2 | I5: Dokumen keikutsertaan Direksi dalam program pengembangan budaya risiko seperti memberikan sosialisasi, kehadiran dalam dalam suatu program budaya risiko (notulen rapat, absensi, dll). Dokumen Surat keputusan Direksi untuk pelaksanaan program budaya risiko atau lain-lainya yang terkait (misal tercantum dalam kebijakan budaya kerja perusahaan atau kebijakan menajemen risiko, atau yang lainnya).
F6: d | G6: Telah ada evaluasi rutin yang dilakukan minimal 1 kali per tahun terhadap peningkatan budaya risiko (misal survei budaya risiko) termasuk mengumpulkan masukan dari pegawai untuk pengembangan program budaya risiko. | H6: 1 | I6: Dokumen hasil evaluasi terhadap pelaksanaan budaya risiko yang terkait dengan peningkatan budaya risiko (misalnya survey budaya risiko) dan masukan dari pegawai untuk pengembangan program budaya risiko.
F7: e | G7: Budaya risiko menjadi bagian integral dari budaya perusahaan. Budaya risiko tercantum pada kebijakan budaya kerja yang disosialisasi kan di perusahaan, dan budaya ini tertanam di seluruh lini perusahaan dimulai dengan penegasan dari jajaran manajemen, diperkuat dengan langkah nyata (yang juga dapat digunakan sebagai kriteria evaluasi kinerja pegawai): o Cepat mengantisipasi potensi risiko dan menanggapinya dengan tepat. o Menyeimbangkan target jangka pendek dan risiko jangka panjang. o Pembahasan risiko yang sulit tetap dilakukan secara konstruktif o Mendukung pelaksanaan inisiatif Manajemen Risiko dan secara ketat menerapkan pedoman Manajemen Risiko o Resiliensi (contohnya resiliensi operasional, tanggap merespon peristiwa yang merugikan, dan sebagainya, dengan memberi penekanan baik dalam penyusunan strategi maupun dalam pelaksanaannya) | H7: 1 2 3 4 5 | I7: Cuplikan dokumen kebijakan budaya perusanaan yang mencantumkan budaya risiko. Dokumen laporan hasil pelaksanaan sosialisasi budaya perusahaan yang didalamnya juga tercantum budaya risiko ke seluruh perusahaan. Dokumen laporan hasil monitoring pelaksanaan mitigasi risiko utama perusahaan yang telah menggambarkan adanya antispasi yang cepat dan tepat terhadap potensi risikonya. Dokumen laporan hasil pembahasan risiko yang dianggap sulit yang dilengkapi dengan prosedur proses manajemen risiko yang telah ditetapkan (misal notulen rapat). Dokumen laporan hasil pelaksanaan contingensi plan ketika terjadi sesuatu yang merugikan dimana eksposur risiko sudah melewati toleransi risiko.
F8: f | G8: Telah ada serangkaian sistem penunjang untuk pelaksanaan dan penanaman program budaya risiko perusahaan, contohnya: o Intranet perusahaan untuk memuat informasi yang dapat diakses mengenai program budaya risiko dan kebijakan risiko perusahaan. o Tersedia dashboard untuk memantau metrik yang berkaitan dengan budaya risiko/program budaya risiko. | H8: 1 2 | I8: Dokumen surat dari perusahaan tentang penggunaan sistem penunjang untuk pelaksanaan dan penanaman program budaya risiko perusahaan seperti penggunaan intranet yang dapat diakses mengenai program budaya risiko dan kebijakan risiko perusahaan oleh seluruh pegawai (screen shoot dari tampilan intranet yang digunakan). Dokumen yang menunjukkan adanya dash board untuk memantau metrik yang berkaitan dengan budaya risiko/program budaya risiko.
F9: g | G9: Telah ada bukti yang jelas atas kinerja implementasi program budaya risiko, di antaranya: o Bukti perbaikan indikator utama berkaitan dengan budaya risiko perusahaan, di antaranya penurunan jumlah kasus kecurangan internal, korupsi, dan pelanggaran kode etika pegawai, beserta penurunan jumlah kerugian dari kasus pelanggaran tersebut. o Penyelesaian penuh program budaya risiko bagi pegawai yang telah direncana kan dalam periode pelaporan. | H9: 1 2 | I9: Dokumen hasil evaluasi terhadap indikator utam terkait budaya risiko seperti adanya penurunan kasus kecurangan, korupsi, pelanggaran kode etik, dan penurunan jumlah kerugian akibat kasus tersebut dari tahun yang lalu dengan tahun yang diukur. Dokumen laporan hasil pelaksanaan program budaya risiko di tahun yang diukur dan terbukti program yang direncanakan telah dilaksanakan 100%.
B10: 2 | C10: Kapabilitas Risiko | D10: 2 | E10: Peran penilaian RMI dalam upaya peningkatan praktik manajemen risiko. | F10: a | G10: Telah ada Penilaian RMI yang telah diformalisasikan ke dalam kebijakan Risiko perusahaan | H10: 1 | I10: Cuplikan Dokumen kebijakan manajemen risiko yang didalamnya telah memformalisasikan penilaian RMI.
F11: b | G11: Penilaian RMI dilakukan secara rutin (setiap tahun) dan telah dilaksanakan dengan baik di level Holding dan setiap anak perusahaan (jika relevan) | H11: 1 | I11: Dokumen laporan hasil pelaksanaan RMI minimal 3 tahun terakhir.
F12: c | G12: Penilaian RMI mencakup seluruh Dimensi (budaya dan kapabilitas Risiko, organisasi dan tata kelola Risiko, kerangka Risiko dan kepatuhan, proses dan kontrol Risiko, serta model, data, dan teknologi Risiko) | H12: 1 2 | I12: Dokumen yang menyatakan bahwa pelaksanaan penilaian RMI tahun yang diukur sudah sesuai dengan Juknis 8 Per-2 BUMN 2023 (misal notulen rapat, cuplikan dokumen kebijakan manajemen risiko, SK, dll). Cuplikan dokumen Laporan penilaian RMI yang memuat dimensi risiko yang diukur.
F13: d | G13: Telah ada rencana perbaikan atas hasil Penilaian RMI dengan tindak lanjut yang jelas (terdapat inisiatif mendetail dengan penanggung jawab, lini masa implementasi terperinci) | H13: 1 | I13: Dokumen rinci rencana perbaikan atas hasil penilaian RMI tahun sebelumnya.
F14: e | G14: Telah ada sosialisasi atas hasil Penilaian RMI dan pemantauan progres tindak lanjut atas rekomendasi Penilaian RMI yang terdokumentasi dengan baik kepada Direksi dan Dewan Komisaris serta pemangku kepentingan terkait (misal semua personel Manajemen Risiko, beserta personel Lini Pertama/Lini Ketiga terkait) untuk memper-kuat kepemilikan kematangan Risiko di antara semua pihak yang berkepentingan. | H14: 1 2 | I14: Dokumen bukti pelaksanaan sosialisasi atas hasil Penilaian RMI dan pemantauan progres tindak lanjut atas rekomendasi Penilaian RMI kepada Direksi dan Dewan Komisaris serta pemangku kepentingan terkait. ( laporan sosialisasi, notulen rapat, presentasi PPT, dll). Dokumen pemantauan tindak lanjut atas rekomendasi Penilaian RMI.
F15: f | G15: Telah ada bukti yang jelas atas kinerja implementasi rekomendasi Penilaian RMI, di antaranya: o Peningkatan skor RMI secara year-on-year, baik di level Holding maupun anak perusahaan (jika relevan). o Inisiatif dan rencana tindakan perbaikan dilaksanakan sepenuhnya (100%) selama periode pelaporan sesuai dengan peta jalan dan lini masa yang telah disusun. | H15: 1 2 | I15: Dokumen yang membuktikan telah adanya peningkatan skor RMI dari tahun ke tahun minimal 3 tahun terakhir ( hasil evaluasi pelaksanaan RMI 3 tahun terakhir atau cuplikan dokumen penilaian RMI 3 tahun terakhir yang mencantumkan skor RMI-nya). Dokumen laporan hasil monitoring pelaksanaan inisiatif dan rencana tindakan perbaikan telah dilaksanakan sepenuhnya (100%) selama periode pelaporan sesuai dengan peta jalan dan lini masa yang telah disusun.
F16: g | G16: Telah dilakukan verifikasi/ audit Penilaian RMI oleh pihak independen (misal audit internal, atau tinjauan oleh pihak eksternal independen) sebagai “check-and-balance” untuk meminimalisir potensi bias dalam penilaian. | H16: 1 | I16: Dokumen laporan hasil audit intern atau esktern atas hasil penilaian RMI oleh pihak independen (audit intern atau audit ekstern).
D17: 3 | E17: Program peningkatan keahlian risiko | F17: a | G17: Telah ada program peningkatan keahlian risiko. | H17: 1 | I17: Dokumen program peningkatan keahlian risiko bagi pegawai yang berisikan rencana pelatihan keahlian risiko, workshop manajemen risiko , dll yang akan dijalan pada tahun yang diukur.
F18: b | G18: Program dapat diakses oleh semua pegawai. | H18: 1 2 | I18: Dokumen yang menyatakan bahwa seluruh pegawai wajib mengikuti program peningkatan keahlian risiko sesuai dengan tingkat keahlian/jabatan. Dokumen daftar peserta yang mengikuti program peningkatan risiko dilengkapi dengan unit kerjanya.
F19: c | G19: Program bersifat wajib dan rutin (paling sedikit satu kali dalam setahun), dan telah diterapkan sanksi untuk ketidakhadiran. | H19: 1 2 | I19: Dokumen yang menyatakan bahwa program peningkatan keahlian risiko bersifat wajib seperti surat perintah direksi atau yang lainnya. Dokumen laporan hasil pengenaan sanksi atas ketidakhadiran dalam program peningkatan keahlian risiko.
F20: d | G20: Program disesuaikan dengan tingkat keahlian/jabatan, khususnya untuk personel risiko dan anggota Dewan Komisaris/Direksi. | H20: 1 | I20: Dokumen yang membuktikan bahwa Program sudah disesuaikan dengan tingkat keahlian/jabatan, khususnya untuk personel risiko dan anggota Dewan Komisaris/Direksi (misal silabus training atau yang lainnya).
F21: e | G21: Topik program bersifat komprehensif (mencakup seluruh Dimensi manajemen risiko seperti budaya dan kapabilitas Risiko, organisasi dan tata kelola Risiko, kerangka Risiko dan kepatuhan, proses dan kontrol Risiko, serta model, data, dan teknologi Risiko). | H21: 1 | I21: Dokumen yang membuktikan bahwa program sudah bersifat komprehensif mencakup seluruh Dimensi manajemen risiko ( misal silabus training atau yang lainnya).
F22: f | G22: Tingkat kehadiran pelatihan di atas 95% dari jumlah peserta yang terdaftar. | H22: 1 | I22: Dokumen yang membuktikan tingkat kehadiran pelatihan di atas 95% dari jumlah peserta yang terdaftar (misal absensi yang bukan tulisan tangan).
F23: g | G23: Kurikulum ditinjau secara rutin dan formal berdasarkan kebutuhan pelatihan pegawai, serta melalui proses pembaruan setiap tahun untuk memastikan kualitas nya dan diperbarui agar sesuai dengan risiko-risiko utama dan praktik terbaik Manajemen Risiko (misal terus diperbarui dengan standar internasional terkini). | H23: 1 | I23: Dokumen hasil evaluasi atau tinjauan terhadap kurikulum atau silabus program peningkatan keahlian risiko minimal 3 tahun terakhir.
F24: h | G24: Telah ada “feedback-loop”/ pengumpulan feedback terdokumentasi dari pegawai yang telah menerima pelatihan risiko, untuk menilai manfaat dari pelatihan risiko terhadap keahlian pegawai dalam menjalankan pekerjaannya, serta memberikan masukan untuk pengembangan program pelatihan secara berkesinambungan. | H24: 1 | I24: Dokumen laporan hasil evaluasi pengumpulan feedback terdokumentasi dari pegawai yang telah menerima pelatihan risiko.
F25: i | G25: Telah dilakukan analisis untuk menilai keberhasilan/ruang perbaikan program, termasuk area-area di mana pegawai belum menunjukkan kinerja yang baik dan membutuh kan pelatihan/tes lebih lanjut pada siklus pelatihan berikutnya. | H25: 1 | I25: Dokumen laporan hasil analisis untuk menilai keberhasilan/ruang perbaikan program.
F26: j | G26: Perusahaan terus melakukan terobosan dalam pembelajaran melalui kolaborasi dengan penyedia program pelatihan Manajemen Risiko sesuai industri yang dijalankannya untuk mengedukasi pegawainya terkait praktik terbaik global Manajemen Risiko (khususnya untuk pegawai di jabatan Manajemen penting/ personel Unit Bisnis dan divisi Manajemen Risiko). | H26: 1 2 | I26: Dokumen laporan atau evaluasi hasil pembelajaran melalui kolaborasi dengan penyedia program pelatihan Manajemen Risiko sesuai industri yang dijalankannya. Dokumen bukti sertifikat training yang telah dilaksanakan kususnya untuk pegawai di jabatan Manajemen penting/ personel Unit Bisnis dan divisi Manajemen Risiko oleh penyedia program pelatihan manajemen risiko.
F27: k | G27: Telah ada bukti yang jelas atas kinerja implementasi pelatihan risiko, di antaranya: o Penyelesaian penuh untuk pelatihan wajib terkait manajemen risiko/ kesadaran risiko untuk semua pegawai. o Penyelesaian penuh pelatihan risiko berdasarkan tingkat keahlian/jabatan untuk pegawai utama, terutama mereka yang memegang posisi manajerial di Lini Pertama, Lini Kedua, dan Lini Ketiga (kebutuhan/keluaran pelatihan terpenuhi). o Telah ada bukti sanksi yang diterapkan kepada pegawai yang tidak menyelesaikan program pelatihan terkait manajemen risiko yang telah diwajibkan. | H27: 1 2 3 4 | I27: Dokumen laporan hasil pelaksanaan pelatihan keahlian risiko tahun yang diukur. Sertifikat pelatihan wajib terkait manajemen risiko untuk semua karyawan. Sertifikat pelatihan risiko berdasarkan tingkat keahlian/jabatan untuk pegawai utama, terutama mereka yang memegang posisi manajerial di Lini Pertama, Lini Kedua, dan Lini Ketiga. Laporan ketidakhadiran peserta yang telah dijadwalkan beserta sanksi yang diberikan.
B28: 3 | C28: Organ Pengelola Risiko | D28: 4 | E28: Efektifitas Fungsi pengelola risiko | F28: a | G28: Telah ada fungsi risiko khusus dengan akuntabilitas perorangan dan cara interaksi yang jelas dengan fungsi kontrol maupun dengan Unit Bisnis. | H28: 1 | I28: Dokumen SK untuk nama-nama Risk Management Officer untuk setiap unit kerja.
F29: b | G29: Telah ada Direktur yang bertanggung jawab atas risiko, sesuai dengan klasifikasi risiko dan komposisi organ yang diatur dalam Petunjuk Teknis Komposisi dan Kualifikasi Organ Pengelola Risiko. | H29: 1 | I29: Dokumen SK organisasi atau cuplikan dokumen Kebijakan Manajemen Risiko yang menyatakan telah ada Direktur yang bertanggung jawab atas risiko, sesuai dengan klasifikasi risiko dan komposisi organ yang diatur dalam Petunjuk Teknis Komposisi dan Kualifikasi Organ Pengelola Risiko.
F30: c | G30: Telah ada fungsi Manajemen Risiko dan kepatuhan independen sebagai Lini Kedua,dan menjalankan tugasnya untuk menyusun metodologi dan kebijakan Manajemen Risiko. | H30: 1 | I30: Dokumen SK organisasi atau cuplikan dokumen Kebijakan Manajemen Risiko yang menyatakan telah ada fungsi Manajemen Risiko dan kepatuhan independen sebagai Lini Kedua,dan menjalankan tugasnya untuk menyusun metodologi dan kebijakan Manajemen Risiko.
F31: d | G31: Fungsi risiko (dengan dukungan dari fungsi kepatuhan) memiliki kewenangan untuk menjalankan tanggung jawab utamanya yaitu: • Mengidentifikasi risiko • Mengukur risiko • Memonitor risiko • Mengontrol atau memitigasi risiko • Melaporkan eksposur risiko | H31: 1 | I31: Dokumen SK organisasi atau cuplikan dokumen Kebijakan Manajemen Risiko yang menyatakan Fungsi risiko (dengan dukungan dari fungsi kepatuhan) memiliki kewenangan untuk menjalankan tanggung jawab utamanya yaitu: • Mengidentifikasi risiko • Mengukur risiko • Memonitor risiko • Mengontrol atau memitigasi risiko • Melaporkan eksposur risiko
F32: e | G32: Fungsi Assurance bersifat independen dan bertugas untuk memastikan bahwa manajemen dan pengendalian risiko dilakukan secara efektif (internal audit). | H32: 1 | I32: Dokumen SK organisasi atau cuplikan dokumen Kebijakan Manajemen Risiko atau kebijakan yang lainnya yang menyatakan Fungsi Assurance bersifat independen dan bertugas untuk memastikan bahwa manajemen dan pengendalian risiko dilakukan secara efektif (internal audit).
F33: f | G33: Telah ada pimpinan khusus yang diformalisasikan (di tingkat manajemen) untuk setiap risiko utama (misal pimpinan khusus untuk risiko proyek, risiko strategis, risiko pasar, dll.) yang selaras antara penanggung jawab dan konteks bisnisnya. | H33: 1 | I33: Dokumen SK oragnisasi yang menugaskan pimpinan khusus yang diformalisasikan (di tingkat manajemen) untuk setiap risiko utama (misal pimpinan khusus untuk risiko proyek, risiko strategis, risiko pasar, dll.) yang selaras antara penanggung jawab dan konteks bisnisnya.
F34: g | G34: Akuntabilitas Direktorat Risiko disampaikan kepada Komite Pemantau Risiko dengan alur pelaporan yang jelas. | H34: 1 | I34: Dokumen SK organisasi atau cuplikan dokumen Kebijakan Manajemen Risiko atau kebijakan yang lainnya yang memuat alur pelaporan yang jelas tentang penyampaian akuntabilitas Direktorat Risiko kepada Komite Pemantau Risiko.
F35: h | G35: Struktur tata kelola risiko yang jelas untuk setiap Unit Bisnis di bawah payung Grup (struktur tata kelola disesuaikan untuk risiko- risiko khusus seperti risiko siber). | H35: 1 | I35: Dokumen SK organisasi atau cuplikan dokumen Kebijakan Manajemen Risiko atau kebijakan yang lainnya yang memuat struktur tata kelola risiko yang jelas untuk setiap Unit Bisnis di bawah payung Grup (struktur tata kelola disesuaikan untuk risiko- risiko khusus seperti risiko siber).
F36: i | G36: Telah ada bukti yang jelas atas kinerja optimalisasi struktur tata kelola risiko, di antaranya: telah dilaksanakan penyesuaian berkala (misal setiap tahun) struktur organisasi risiko (beserta penunjukan yang jelas untuk pimpinan yang bertanggung jawab atas risiko risiko utama perusahaan). | H36: 1 2 | I36: Dokumen laporan hasil evaluasi atau tinjuan berkala atas struktur tata kelola risiko atau SK untuk penentuan struktur tata kelola risiko 3 tahun terakhir atau culikan dokumen revisi pedoman manajemen risiko yang berisikan struktur tata kelola risiko. Surat penunjukan yang jelas untuk pimpinan yang bertanggung jawab atas risiko risiko utama perusahaan.
D37: 5 | E37: Tingkat kematangan organ pengelola risiko | F37: a | G37: Telah terpenuhinya kelengkapan organ pengelola risiko sesuai klasifikasi risiko BUMN serta fungsi, tugas, dan tanggung jawabnya sudah sesuai sebagaimana ketentuan dalam PER-2/MBU/03/ 2023 maupun Petunjuk Teknis mengenai Komposisi dan Kualifikasi Organ Pengelola Risiko. | H37: 1 | I37: Dokumen SK atau cuplikan pada kebijakan manajemen risiko atau kebijakan lainnya tentang organ pengelola risiko beserta fungsi, tugas dan tanggung jawabnya.
F38: b | G38: BUMN telah memiliki proses formal untuk mengelola risiko yang dituangkan dalam kebijakan/pedoman manajemen risiko. | H38: 1 | I38: Dokumen kebijakan/ pedoman manajemen risiko.
F39: c | G39: Fungsi risiko memiliki keterampilan dalam pengendalian dan pemodelan risiko sebagai dasar pengambilan keputusan berdasarkan selera risiko BUMN dan memberikan kontribusi terhadap kinerja BUMN. | H39: 1 2 | I39: Dokumen sertifikasi profesi manajemen risiko yang dipunyai oleh fungsi risiko yaitu unit SPI, Unit Manajemen Risiko, dan Unit kerja lainnya yang diwakili oleh Risk Officer. Dokumen pencapaian target (KPI) perusahaan tahun yang diukur dan terbukti tercapai atau melebihi target.
F40: d | G40: Seluruh organ pengelola Risiko telah tersertifikasi Manajemen Risiko lebih dari 1 sertifikasi. | H40: 1 | I40: Dokumen sertifikasi manajemen risiko lebih dari satu yang dimiliki oleh organ pengleola risiko: o Dewan Komisaris/ Pengawas, o Direksi, o Komite Pemantau Risiko. o Komite Tata Kelola Terintegrasi. o Direktur yang membidangi pengelolaan risiko. o Direktur yang membidangi pemgelolaan keuangan o SPI
F41: e | G41: Praktik terbaik tata kelola risiko diterapkan di induk dan semua anak perusahaan (jika relevan). | H41: 1 | I41: Dokumen kebijakan/ pedoman manajemen risiko atau tata kelola risiko telah terkini dengan praktik terbaik tata kelola risiko.
...

Sheet Score Dimensi
B2: DIMENSI | D2: SUB DIMENSI | F2: PARAMETER | H2: SKOR PARAMETER | I2: SKOR DIMENSI
B3: 1 | C3: Budaya dan Kapablitas Risiko | D3: a | E3: Budaya Risiko | F3: 1 | G3: Internalisasi budaya risiko dalam budaya perusahaan | H3: ='Reviu Dokumen'!N3 -> 0 | I3: =AVERAGE(H3:H5) -> 0
D4: b | E4: Kapabilitas Risiko | F4: 2 | G4: Peran penilaian RMI dalam upaya peningkatan praktik Manajemen Risiko | H4: ='Reviu Dokumen'!N10 -> 0
F5: 3 | G5: Program Peningkatan keahlian risiko | H5: ='Reviu Dokumen'!N17 -> 0
B6: 2 | C6: Organisasi dan Tata Kelola risiko | D6: a | E6: Organ Pengelola Risisko | F6: 4 | G6: Efektivitas pengelola risiko | H6: ='Reviu Dokumen'!N28 -> 0 | I6: =AVERAGE(H6:H21) -> 0
F7: 5 | G7: Tingkat kematangan organ pengelola risiko | H7: ='Reviu Dokumen'!N37 -> 0
D8: b | E8: Peran dan Tanggung Jawab Organ Pengelola Risiko | F8: 6 | G8: Keterlibatan aktik Dekom/ Dewas dalam pengelolaan risiko | H8: ='Reviu Dokumen'!N43 -> 0
F9: 7 | G9: Eskalasi permasalahan kepada Dekom/ Dewas | H9: ='Reviu Dokumen'!N50 -> 0
F10: 8 | G10: Tingkat pemahaman risiko di jajaran Dekom/ Dewas | H10: ='Reviu Dokumen'!N53 -> 0
F11: 9 | G11: Peran Komite-Komite di bawah Dekom/ Dewas | H11: ='Reviu Dokumen'!N60 -> 0
F12: 10 | G12: Pengurusan aktif Direksi dalam pengelolaan risiko | H12: ='Reviu Dokumen'!N66 -> 0
F13: 11 | G13: Mandat, wewenang, dan independensi fungsi manajemen risiko untuk memantau semua risiko | H13: ='Reviu Dokumen'!N75 -> 0
F14: 12 | G14: Efektivitas pengelola risiko dalam menjalankan tugasnya | H14: ='Reviu Dokumen'!N83 -> 0
D15: c | E15: Model Tata Kelola Risiko Tiga Lini dan Tata Kelola Terintegrasi | F15: 13 | G15: Penerapan model tata kelola tiga lini | H15: ='Reviu Dokumen'!N87 -> 0
F16: 14 | G16: Peran dan fungsi lini pertama | H16: ='Reviu Dokumen'!N94 -> 0
F17: 15 | G17: Peran dan fungsi lini kedua | H17: ='Reviu Dokumen'!N101 -> 0
F18: 16 | G18: Peran dan fungsi lini ketiga | H18: ='Reviu Dokumen'!N108 -> 0
F19: 17 | G19: Interaksi antara fungsi risiko dan assurance | H19: ='Reviu Dokumen'!N114 -> 0
F20: 18 | G20: Peran dan fungsi tata kelola terintegrasi | H20: ='Reviu Dokumen'!N119 -> 0
F21: 19 | G21: Monitoring risiko entitas induksampai entitas anak | H21: ='Reviu Dokumen'!N128 -> 0
B22: 3 | C22: Kerangka Risiko dan Kepatuhan | D22: a | E22: Strategi Risiko | F22: 20 | G22: Peningkatan kualitas kerangka manajemen risiko | H22: ='Reviu Dokumen'!N133 -> 0 | I22: =AVERAGE(H22:H35) -> 0
F23: 21 | G23: Rencana transformasi Enterprise Risk Management (ERM) | H23: ='Reviu Dokumen'!N138 -> 0
F24: 22 | G24: Peran manajemen risiko dalam penyusunan rencana strategis | H24: ='Reviu Dokumen'!N144 -> 0
F25: 23 | G25: Hubungan peran manajemen risiko terhadap pencapaian target strategsi RKAP | H25: ='Reviu Dokumen'!N150 -> 0
F26: 24 | G26: Kapasitas risiko | H26: ='Reviu Dokumen'!N153 -> 0
F27: 25 | G27: Selera risiko | H27: ='Reviu Dokumen'!N159 -> 0
F28: 26 | G28: Komunikasi selera risiko kepada pemangku kepentingan eksternal | H28: ='Reviu Dokumen'!N168 -> 0
D29: b | E29: Kebijakan dan Prosedur | F29: 27 | G29: Kebijakan risiko | H29: ='Reviu Dokumen'!N171 -> 0
F30: 28 | G30: Prosedur risiko | H30: ='Reviu Dokumen'!N179 -> 0
F31: 29 | G31: Rencana darurat (contingency plan) dalam kondisi terburuk (worst case scenario) | H31: ='Reviu Dokumen'!N184 -> 0
F32: 30 | G32: Reviu dan stress test terhadap prosedur dan SOP | H32: ='Reviu Dokumen'!N190 -> 0
D33: c | E33: Fungsi Kepatuhan | F33: 31 | G33: Organ fungsi kepatuhan dan perannya | H33: ='Reviu Dokumen'!N194 -> 0
D34: d | E34: Efektivitas Manajemen Risiko dan Pengendalian Internal | F34: 32 | G34: Penerapan kerangka integrated ERM | H34: ='Reviu Dokumen'!N201 -> 0
F35: 33 | G35: Efektivitas pengendalian internal | H35: ='Reviu Dokumen'!N208 -> 0
B36: 4 | C36: Proses dan Kontrol Risiko | D36: a | E36: Identifikasi Risiko | F36: 34 | G36: Identifikasi risiko utama | H36: ='Reviu Dokumen'!N219 -> 0 | I36: =AVERAGE(H36:H42) -> 0
D37: b | E37: Pengukuran dan Prioritisasi Risiko | F37: 35 | G37: Pengukuran risiko | H37: ='Reviu Dokumen'!N230 -> 0
F38: 36 | G38: Kerangka proses pengukuran risiko untuk prioritisasi risiko | H38: ='Reviu Dokumen'!N235 -> 0
F39: 37 | G39: Agregasian atas seluruh risiko utama | H39: ='Reviu Dokumen'!N242 -> 0
D40: c | E40: Perlakuan Risiko | F40: 38 | G40: Aktivitas perlakuan atas risiko utama | H40: ='Reviu Dokumen'!N248 -> 0
F41: 39 | G41: Proses identifikasi dan pengelolaan risiko yang berada di atas selera risiko | H41: ='Reviu Dokumen'!N258 -> 0
...

Sheet Score RMI
B33: ASPEK DIMENSI
B34: Parameter | C34: Dimensi | D34: Deskripsi | E34: Skor Dimensi | F34: Skor
B35: 1 s.d. 3 | C35: 1 | D35: Budaya dan Kapabiltas Risiko | E35: ='Score Dimensi'!I3 -> 0
B36: 4 s.d. 19 | C36: 2 | D36: Organisasi dan Tata Kelola Risiko | E36: ='Score Dimensi'!I6 -> 0
B37: 20 s.d. 33 | C37: 3 | D37: Kerangka Risiko dan Kepatuhan | E37: ='Score Dimensi'!I22 -> 0
B38: 34 s.d. 39 | C38: 4 | D38: Proses dan Kontrol Risiko | E38: ='Score Dimensi'!I36 -> 0
B39: 40 s.d. 42 | C39: 5 | D39: Model, Data, dan Teknologi Risiko | E39: ='Score Dimensi'!I43 -> 0
B40: 1 s.d. 42 | C40: Skor Aspek Dimensi | F40: ='Score Dimensi'!I46 -> 0
H42: ASPEK KINERJA
H43: No | I43: Aspek | J43: Nilai Aspek | K43: Nilai Konversi | L43: Bobot | M43: Nilai Konversi x Bobot | N43: Skor
H44: 1 | I44: Tingkat Kesehatan Peringkat Akhir (Final Rating) | L44: 0.5 | M44: =K44*L44 -> 0
H45: 2 | I45: Peringkat Komposit Risiko | L45: 0.5 | M45: =K45*L45 -> 0
H46: 1 sd 2 | I46: Skor Aspek Kinerja | N46: =M44+M45 -> 0
I47: Penyesuaian Skor
H48: SKOR RMI | N48: =F40+N47 -> 0

Sheet Keterangan Pengisian
E5: Dokumen yang harus ada | H5: Screen shoot Dokumen | I5: Nila Score Kriteria | J5: Nilai Score Parameter
B20: PADA SHEET "REVIU DOKUMEN"
B21: Pada kolom dokumen yang harus disiapkan, di situ adalah keterangan dokumen apa yang harus ada. Ini hanya sebuah bantuan untuk memudahkan dokumen yang harus disiapkan. Untuk nama nama dokumennya bisa dilihat pada juknis.
B22: Pada kolom reviu dokumen diisikan hasil dari evaluasi antara dokumen yang sudah terkumpul dengan kriterianya.
B23: Pada kolom screenshoot dokumen, screen shoot nya bisa dikecilkan sehingga dapat dimuat di situ. Nanti dalam laporan jika punya format berbeda dapat dibesarkan lagi. Ini hanya untuk mempermudah untuk melihat semuanya dalam satu sheet.
B24: Pada kolom score kriteria diisikan score dari setiap krteria sesuai dengan ketentuan.
B25: Pada kolom score parameter diisikan nilai dari parameter yang diambil dari nilai kriteria terkecil dari nilai kriteria yang ada di parameter tersebut.
B26: Kriteria dalam pengujian ini adalah untuk RMI Umum, untuk bank dan asuransi dapat dibuat sendiri, mungkin dengan mengikuti pola yang ada pada kriteria umum ini. Untuk rumus-rumus formulanya bisa disesuai kriteria bank dan asuransi.
B43: Pada "SHEET SCORE DIMENSI" , tidak usah mengisi apa-apa karena sudah terisi otomatis berdasarkan isian pada sheet Reviu Dokumen (gambar di atas hanya cuplikan perhitungan score aspek dimensi)
B55: SHEET SCORE RMI:
B56: Pada sheet Score RMI yang diisi adalah kolom Nilai aspek, Nilai Konversi, serta Penyesuaian Score. Penyesuaian score diambil dari tabel yang sudah ditentukan. Pada contoh nilai 77.5 nilai penyesuaiannya adalah 0.5.
B58: Pada score Nilai aspek, Peringkat Komposit adalah 3 karena nilai Kinerjuanya baik namun nilai KPMR nya Marginal sehingga score nya adalah 3 dan nilai konversinya adalah 55.
B60: Sehingga Nilai SKOR RMI akhirnya adalah 3.1 - 0.5 = 2.6
B62: Jika score aspek dimensinya kurang dari 3, maka nilai aspek kinerja tidak dihitung, jadi nilai RMI nya hanya nilai aspek dimensinya saja.
